<?xml version="1.0" ?>
<!-- =================================================================================== -->
<!-- |    This document was autogenerated by xacro from mybot.urdf.xacro               | -->
<!-- |    EDITING THIS FILE BY HAND IS NOT RECOMMENDED                                 | -->
<!-- =================================================================================== -->
<robot name="mybot">
  <!-- Init colour -->
  <material name="black">
    <color rgba="0.0 0.0 0.0 1.0"/>
  </material>
  <material name="dark">
    <color rgba="0.3 0.3 0.3 1.0"/>
  </material>
  <material name="light_black">
    <color rgba="0.4 0.4 0.4 1.0"/>
  </material>
  <material name="blue">
    <color rgba="0.0 0.0 0.8 1.0"/>
  </material>
  <material name="green">
    <color rgba="0.0 0.8 0.0 1.0"/>
  </material>
  <material name="grey">
    <color rgba="0.5 0.5 0.5 1.0"/>
  </material>
  <material name="orange">
    <color rgba="1.0 0.4235294117647059 0.0392156862745098 1.0"/>
  </material>
  <material name="brown">
    <color rgba="0.8705882352941177 0.8117647058823529 0.7647058823529411 1.0"/>
  </material>
  <material name="red">
    <color rgba="0.8 0.0 0.0 1.0"/>
  </material>
  <material name="white">
    <color rgba="1.0 1.0 1.0 1.0"/>
  </material>
  <gazebo reference="base_link">
    <material>Gazebo/DarkGrey</material>
  </gazebo>
  <gazebo reference="wheel_left_link">
    <mu1>0.1</mu1>
    <mu2>0.1</mu2>
    <kp>500000.0</kp>
    <kd>10.0</kd>
    <minDepth>0.001</minDepth>
    <maxVel>0.1</maxVel>
    <fdir1>1 0 0</fdir1>
    <material>Gazebo/FlatBlack</material>
  </gazebo>
  <gazebo reference="wheel_right_link">
    <mu1>0.1</mu1>
    <mu2>0.1</mu2>
    <kp>500000.0</kp>
    <kd>10.0</kd>
    <minDepth>0.001</minDepth>
    <maxVel>0.1</maxVel>
    <fdir1>1 0 0</fdir1>
    <material>Gazebo/FlatBlack</material>
  </gazebo>
  <gazebo reference="caster_back_link">
    <mu1>0.1</mu1>
    <mu2>0.1</mu2>
    <kp>1000000.0</kp>
    <kd>100.0</kd>
    <minDepth>0.001</minDepth>
    <maxVel>1.0</maxVel>
    <material>Gazebo/FlatBlack</material>
  </gazebo>
  <gazebo reference="imu_link">
    <sensor name="imu" type="imu">
      <always_on>true</always_on>
      <visualize>false</visualize>
    </sensor>
    <material>Gazebo/FlatBlack</material>
  </gazebo>
  <gazebo>
    <plugin filename="libgazebo_ros_diff_drive.so" name="turtlebot3_burger_controller">
      <commandTopic>cmd_vel</commandTopic>
      <odometryTopic>odom</odometryTopic>
      <odometryFrame>odom</odometryFrame>
      <odometrySource>world</odometrySource>
      <publishOdomTF>true</publishOdomTF>
      <robotBaseFrame>base_footprint</robotBaseFrame>
      <publishWheelTF>false</publishWheelTF>
      <publishTf>true</publishTf>
      <publishWheelJointState>true</publishWheelJointState>
      <legacyMode>false</legacyMode>
      <updateRate>30</updateRate>
      <leftJoint>wheel_left_joint</leftJoint>
      <rightJoint>wheel_right_joint</rightJoint>
      <wheelSeparation>0.160</wheelSeparation>
      <wheelDiameter>0.066</wheelDiameter>
      <wheelAcceleration>1</wheelAcceleration>
      <wheelTorque>10</wheelTorque>
      <rosDebugLevel>na</rosDebugLevel>
    </plugin>
  </gazebo>
  <gazebo>
    <plugin filename="libgazebo_ros_imu.so" name="imu_plugin">
      <alwaysOn>true</alwaysOn>
      <bodyName>imu_link</bodyName>
      <topicName>imu</topicName>
      <serviceName>imu_service</serviceName>
      <gaussianNoise>0.0</gaussianNoise>
      <updateRate>200</updateRate>
      <imu>
        <noise>
          <type>gaussian</type>
          <rate>
            <mean>0.0</mean>
            <stddev>2e-4</stddev>
            <bias_mean>0.0000075</bias_mean>
            <bias_stddev>0.0000008</bias_stddev>
          </rate>
          <accel>
            <mean>0.0</mean>
            <stddev>1.7e-2</stddev>
            <bias_mean>0.1</bias_mean>
            <bias_stddev>0.001</bias_stddev>
          </accel>
        </noise>
      </imu>
    </plugin>
  </gazebo>
  <gazebo reference="base_scan">
    <material>Gazebo/FlatBlack</material>
    <sensor name="lds_lfcd_sensor" type="ray">
      <pose>0 0 0 0 0 0</pose>
      <visualize>false</visualize>
      <update_rate>5</update_rate>
      <ray>
        <scan>
          <horizontal>
            <samples>360</samples>
            <resolution>1</resolution>
            <min_angle>0.0</min_angle>
            <max_angle>6.28319</max_angle>
          </horizontal>
        </scan>
        <range>
          <min>0.120</min>
          <max>3.5</max>
          <resolution>0.015</resolution>
        </range>
        <noise>
          <type>gaussian</type>
          <mean>0.0</mean>
          <stddev>0.01</stddev>
        </noise>
      </ray>
      <plugin filename="libgazebo_ros_laser.so" name="gazebo_ros_lds_lfcd_controller">
        <topicName>scan</topicName>
        <frameName>base_scan</frameName>
      </plugin>
    </sensor>
  </gazebo>
  <!--bumper turtlebot3 insper-->
  <gazebo reference="bumper_link">
    <sensor name="contacts" type="contact">
      <contact>
        <collision>base_footprint_fixed_joint_lump__base_collision_collision_1</collision>
      </contact>
      <plugin filename="libgazebo_ros_bumper.so" name="gazebo_ros_bumper_controller">
        <always_on>true</always_on>
        <!--  <robotNamespace>/bumper</robotNamespace> -->
        <bumperTopicName>bumper_states</bumperTopicName>
        <frameName>bumper</frameName>
        <visualize>true</visualize>
        <update_rate>50.0</update_rate>
      </plugin>
    </sensor>
    <material>Gazebo/Green</material>
    <mu1>0.1</mu1>
    <mu2>0.1</mu2>
    <gravity>true</gravity>
    <selfCollide>false</selfCollide>
  </gazebo>
  <!--camera turtlebot3 insper-->
  <!--link : https://www.raspberrypi.org/documentation/hardware/camera/-->
  <gazebo reference="camera_rgb_frame">
    <sensor name="Pi Camera" type="camera">
      <always_on>true</always_on>
      <visualize>false</visualize>
      <camera>
        <horizontal_fov>1.085595</horizontal_fov>
        <image>
          <width>640</width>
          <height>480</height>
          <format>R8G8B8</format>
        </image>
        <clip>
          <near>0.03</near>
          <far>100</far>
        </clip>
      </camera>
      <plugin filename="libgazebo_ros_camera.so" name="camera_controller">
        <alwaysOn>true</alwaysOn>
        <updateRate>30.0</updateRate>
        <cameraName>camera</cameraName>
        <frameName>camera_rgb_optical_frame</frameName>
        <imageTopicName>image</imageTopicName>
        <cameraInfoTopicName>camera_info</cameraInfoTopicName>
        <hackBaseline>0.07</hackBaseline>
        <distortionK1>0.0</distortionK1>
        <distortionK2>0.0</distortionK2>
        <distortionK3>0.0</distortionK3>
        <distortionT1>0.0</distortionT1>
        <distortionT2>0.0</distortionT2>
      </plugin>
    </sensor>
  </gazebo>
  <!--garra turtlebot3 insper-->
  <!-- ROS Control -->
  <gazebo>
    <plugin filename="libgazebo_ros_control.so" name="gazebo_ros_control">
      <!-- <robotNamespace>/mybot</robotNamespace> -->
    </plugin>
  </gazebo>
  <!-- loading plugin: mimic joints works in gazebo now -->
  <gazebo>
    <plugin filename="libroboticsgroup_gazebo_mimic_joint_plugin.so" name="gazebo_gripper_ros_control">
      <joint>joint2</joint>
      <mimicJoint>joint3</mimicJoint>
      <multiplier>1.0</multiplier>
      <offset>0.0</offset>
      <!-- <hasPID>mybot/gazebo_ros_control/pid_gains/joint3</hasPID> -->
      <hasPID>gazebo_ros_control/pid_gains/joint3</hasPID>
    </plugin>
  </gazebo>
  <!-- estudar se precisa disso mesmo -->
  <gazebo reference="garra1garrabraco1">
    <kp>1000000.0</kp>
    <kd>100.0</kd>
    <mu1>30.0</mu1>
    <mu2>30.0</mu2>
    <maxVel>1.0</maxVel>
    <minDepth>0.001</minDepth>
    <material>Gazebo/DarkGrey</material>
  </gazebo>
  <gazebo reference="garra1garradireita1">
    <kp>1000000.0</kp>
    <kd>100.0</kd>
    <mu1>30.0</mu1>
    <mu2>30.0</mu2>
    <maxVel>1.0</maxVel>
    <minDepth>0.001</minDepth>
    <material>Gazebo/Green</material>
  </gazebo>
  <gazebo reference="garra1garraesquerda1">
    <kp>1000000.0</kp>
    <kd>100.0</kd>
    <mu1>30.0</mu1>
    <mu2>30.0</mu2>
    <maxVel>1.0</maxVel>
    <minDepth>0.001</minDepth>
    <material>Gazebo/Green</material>
  </gazebo>
  <!-- ROS Transmission -->
  <transmission name="joint1_tran">
    <type>transmission_interface/SimpleTransmission</type>
    <joint name="joint1">
      <!--  <hardwareInterface>hardware_interface/PositionJointInterface</hardwareInterface>-->
      <hardwareInterface>hardware_interface/EffortJointInterface</hardwareInterface>
    </joint>
    <actuator name="joint1_actr">
      <!--  <hardwareInterface>hardware_interface/PositionJointInterface</hardwareInterface>-->
      <hardwareInterface>hardware_interface/EffortJointInterface</hardwareInterface>
      <mechanicalReduction>1</mechanicalReduction>
      <!--para teste hardware_interface/PositionJointInterface
      <motorTorqueConstant>1</motorTorqueConstant>-->
    </actuator>
  </transmission>
  <transmission name="joint2_tran">
    <type>transmission_interface/SimpleTransmission</type>
    <joint name="joint2">
      <!--  <hardwareInterface>hardware_interface/PositionJointInterface</hardwareInterface>-->
      <hardwareInterface>hardware_interface/EffortJointInterface</hardwareInterface>
    </joint>
    <actuator name="joint2_actr">
      <!--  <hardwareInterface>hardware_interface/PositionJointInterface</hardwareInterface>-->
      <hardwareInterface>hardware_interface/EffortJointInterface</hardwareInterface>
      <mechanicalReduction>1</mechanicalReduction>
      <!--para teste hardware_interface/PositionJointInterface
      <motorTorqueConstant>1</motorTorqueConstant>-->
    </actuator>
  </transmission>
  <!-- 
  <transmission name="joint3_tran">
    <type>transmission_interface/SimpleTransmission</type>
    <joint name="joint3">
      <hardwareInterface>hardware_interface/EffortJointInterface</hardwareInterface>
    </joint>
    <actuator name="joint3_actr">
      <hardwareInterface>hardware_interface/EffortJointInterface</hardwareInterface>
      <mechanicalReduction>1</mechanicalReduction>
    </actuator>
  </transmission> -->
  <link name="base_footprint"/>
  <joint name="base_joint" type="fixed">
    <parent link="base_footprint"/>
    <child link="base_link"/>
    <origin rpy="0 0 0" xyz="0.0 0.0 0.010"/>
  </joint>
  <link name="base_link">
    <visual>
      <origin rpy="0 0 0" xyz="-0.032 0 0.0"/>
      <geometry>
        <mesh filename="package://mybot_description/meshes/bases/burger_base.stl" scale="0.001 0.001 0.001"/>
      </geometry>
      <material name="light_black"/>
    </visual>
    <collision>
      <origin rpy="0 0 0" xyz="-0.032 0 0.070"/>
      <geometry>
        <box size="0.140 0.140 0.143"/>
      </geometry>
    </collision>
    <inertial>
      <origin rpy="0 0 0" xyz="0 0 0"/>
      <mass value="8.2573504e-01"/>
      <inertia ixx="2.2124416e-03" ixy="-1.2294101e-05" ixz="3.4938785e-05" iyy="2.1193702e-03" iyz="-5.0120904e-06" izz="2.0064271e-03"/>
    </inertial>
  </link>
  <joint name="wheel_left_joint" type="continuous">
    <parent link="base_link"/>
    <child link="wheel_left_link"/>
    <origin rpy="-1.57 0 0" xyz="0.0 0.08 0.023"/>
    <axis xyz="0 0 1"/>
  </joint>
  <link name="wheel_left_link">
    <visual>
      <origin rpy="1.57 0 0" xyz="0 0 0"/>
      <geometry>
        <mesh filename="package://mybot_description/meshes/wheels/left_tire.stl" scale="0.001 0.001 0.001"/>
      </geometry>
      <material name="dark"/>
    </visual>
    <collision>
      <origin rpy="0 0 0" xyz="0 0 0"/>
      <geometry>
        <cylinder length="0.018" radius="0.033"/>
      </geometry>
    </collision>
    <inertial>
      <origin xyz="0 0 0"/>
      <mass value="2.8498940e-02"/>
      <inertia ixx="1.1175580e-05" ixy="-4.2369783e-11" ixz="-5.9381719e-09" iyy="1.1192413e-05" iyz="-1.4400107e-11" izz="2.0712558e-05"/>
    </inertial>
  </link>
  <joint name="wheel_right_joint" type="continuous">
    <parent link="base_link"/>
    <child link="wheel_right_link"/>
    <origin rpy="-1.57 0 0" xyz="0.0 -0.080 0.023"/>
    <axis xyz="0 0 1"/>
  </joint>
  <link name="wheel_right_link">
    <visual>
      <origin rpy="1.57 0 0" xyz="0 0 0"/>
      <geometry>
        <mesh filename="package://mybot_description/meshes/wheels/right_tire.stl" scale="0.001 0.001 0.001"/>
      </geometry>
      <material name="dark"/>
    </visual>
    <collision>
      <origin rpy="0 0 0" xyz="0 0 0"/>
      <geometry>
        <cylinder length="0.018" radius="0.033"/>
      </geometry>
    </collision>
    <inertial>
      <origin xyz="0 0 0"/>
      <mass value="2.8498940e-02"/>
      <inertia ixx="1.1175580e-05" ixy="-4.2369783e-11" ixz="-5.9381719e-09" iyy="1.1192413e-05" iyz="-1.4400107e-11" izz="2.0712558e-05"/>
    </inertial>
  </link>
  <joint name="caster_back_joint" type="fixed">
    <parent link="base_link"/>
    <child link="caster_back_link"/>
    <origin rpy="-1.57 0 0" xyz="-0.081 0 -0.004"/>
  </joint>
  <link name="caster_back_link">
    <collision>
      <origin rpy="0 0 0" xyz="0 0.001 0"/>
      <geometry>
        <box size="0.030 0.009 0.020"/>
      </geometry>
    </collision>
    <inertial>
      <origin xyz="0 0 0"/>
      <mass value="0.005"/>
      <inertia ixx="0.001" ixy="0.0" ixz="0.0" iyy="0.001" iyz="0.0" izz="0.001"/>
    </inertial>
  </link>
  <joint name="imu_joint" type="fixed">
    <parent link="base_link"/>
    <child link="imu_link"/>
    <origin rpy="0 0 0" xyz="-0.032 0 0.068"/>
  </joint>
  <link name="imu_link"/>
  <joint name="scan_joint" type="fixed">
    <parent link="base_link"/>
    <child link="base_scan"/>
    <origin rpy="0 0 0" xyz="-0.032 0 0.172"/>
  </joint>
  <link name="base_scan">
    <visual>
      <origin rpy="0 0 0" xyz="0 0 0.0"/>
      <geometry>
        <mesh filename="package://mybot_description/meshes/sensors/lds.stl" scale="0.001 0.001 0.001"/>
      </geometry>
      <material name="dark"/>
    </visual>
    <collision>
      <origin rpy="0 0 0" xyz="0.015 0 -0.0065"/>
      <geometry>
        <cylinder length="0.0315" radius="0.055"/>
      </geometry>
    </collision>
    <inertial>
      <mass value="0.114"/>
      <origin xyz="0 0 0"/>
      <inertia ixx="0.001" ixy="0.0" ixz="0.0" iyy="0.001" iyz="0.0" izz="0.001"/>
    </inertial>
  </link>
  <!-- camera turtlebot3 insper-->
  <joint name="camera_joint" type="fixed">
    <origin rpy="0 0.0 0" xyz="0.05 -0.011 0.138"/>
    <parent link="base_link"/>
    <child link="camera_link"/>
  </joint>
  <link name="camera_link">
    <visual>
      <origin rpy="0 0 0" xyz="0.005 0.011 0.013"/>
      <geometry>
        <box size="0.005 0.030 0.027"/>
      </geometry>
    </visual>
    <collision>
      <origin rpy="0 0 0" xyz="0.005 0.011 0.013"/>
      <geometry>
        <box size="0.005 0.030 0.027"/>
      </geometry>
    </collision>
  </link>
  <joint name="camera_rgb_joint" type="fixed">
    <origin rpy="0 0 0" xyz="0.003 0.011 0.009"/>
    <parent link="camera_link"/>
    <child link="camera_rgb_frame"/>
  </joint>
  <link name="camera_rgb_frame"/>
  <joint name="camera_rgb_optical_joint" type="fixed">
    <origin rpy="-1.57 0 -1.57" xyz="0 0 0"/>
    <parent link="camera_rgb_frame"/>
    <child link="camera_rgb_optical_frame"/>
  </joint>
  <link name="camera_rgb_optical_frame"/>
  <!-- bumper turtlebot3 insper-->
  <link name="bumper_link">
    <inertial>
      <origin rpy="0 1.0 0" xyz="0.0 0.0 0.0"/>
      <mass value="0.0000000001"/>
      <inertia ixx="0.00000001" ixy="0.00000001" ixz="0.00000001" iyy="0.00000001" iyz="0.00000001" izz="0.00000001"/>
    </inertial>
    <visual>
      <origin rpy="0.0 1.57 0" xyz="0.0 0.0 0.0"/>
      <geometry>
        <cylinder length="0.015" radius="0.015"/>
      </geometry>
      <material name="green"/>
    </visual>
    <collision name="base_collision">
      <origin rpy="0.0 1.57 0.0" xyz="0.0 0.0 0.0"/>
      <geometry>
        <cylinder length="0.015" radius="0.015"/>
      </geometry>
    </collision>
  </link>
  <joint name="bumper_joint" type="fixed">
    <origin rpy="0.0 0.0 0.0" xyz="0.04 0.0 0.015"/>
    <parent link="base_link"/>
    <child link="bumper_link"/>
  </joint>
  <!-- garra turtlebot3 insper-->
  <joint name="base_joint_garra" type="fixed">
    <parent link="base_link"/>
    <child link="base_link_garra"/>
    <origin rpy="0 0 -1.57" xyz="0.044 0.005 0.108"/>
  </joint>
  <link name="base_link_garra">
    <inertial>
      <origin rpy="0 0 0" xyz="0.0005 -0.0001 0.002"/>
      <mass value="0.0001"/>
      <inertia ixx="1.9768356736455373e-06" ixy="3.3842609487814834e-07" ixz="3.3087224502121107e-23" iyy="2.1568932661454165e-06" iyz="-2.274746684520826e-23" izz="4.120108098287789e-06"/>
    </inertial>
    <visual>
      <origin rpy="0 0 0" xyz="0 0 0"/>
      <geometry>
        <mesh filename="package://mybot_description/meshes/garra/base_link_garra.dae" scale="0.001 0.001 0.001"/>
      </geometry>
      <gazebo reference="base_link_garra">
    </gazebo>
    </visual>
    <collision>
      <origin rpy="0 0 0" xyz="0 0 0"/>
      <geometry>
        <mesh filename="package://mybot_description/meshes/garra/base_link_garra.dae" scale="0.001 0.001 0.001"/>
      </geometry>
    </collision>
  </link>
  <link name="lat31">
    <inertial>
      <origin rpy="0 0 0" xyz="-0.005014384312211391 -0.0015000010654330244 0.013948367968184407"/>
      <mass value="0.0001"/>
      <inertia ixx="8.662089264671677e-08" ixy="0.0" ixz="1.2947458053521905e-11" iyy="1.3378883884262552e-07" iyz="0.0" izz="4.9622899604909504e-08"/>
    </inertial>
    <visual>
      <origin rpy="0 0 0" xyz="-0.007563 0.0205 -0.001"/>
      <geometry>
        <mesh filename="package://mybot_description/meshes/garra/lat31.dae" scale="0.001 0.001 0.001"/>
      </geometry>
      <gazebo reference="lat31">
    </gazebo>
    </visual>
    <collision>
      <origin rpy="0 0 0" xyz="-0.007563 0.0205 -0.001"/>
      <geometry>
        <mesh filename="package://mybot_description/meshes/garra/lat31.dae" scale="0.001 0.001 0.001"/>
      </geometry>
    </collision>
  </link>
  <link name="lat11">
    <inertial>
      <origin rpy="0 0 0" xyz="-0.00149999999999997 0.004954936394439788 0.013948367968184407"/>
      <mass value="0.0001"/>
      <inertia ixx="1.3378883884262488e-07" ixy="-2.6469779601696886e-23" ixz="0.0" iyy="8.66208926467172e-08" iyz="1.294745805340279e-11" izz="4.962289960490908e-08"/>
    </inertial>
    <visual>
      <origin rpy="0 0 0" xyz="0.016 0.0 -0.001"/>
      <geometry>
        <mesh filename="package://mybot_description/meshes/garra/lat11.dae" scale="0.001 0.001 0.001"/>
      </geometry>
      <gazebo reference="lat11">     
    </gazebo>
    </visual>
    <collision>
      <origin rpy="0 0 0" xyz="0.016 0.0 -0.001"/>
      <geometry>
        <mesh filename="package://mybot_description/meshes/garra/lat11.dae" scale="0.001 0.001 0.001"/>
      </geometry>
    </collision>
  </link>
  <link name="lat21">
    <inertial>
      <origin rpy="0 0 0" xyz="0.004954582993387833 0.0014999998509883788 0.013948367968184407"/>
      <mass value="0.0001"/>
      <inertia ixx="8.66208926467172e-08" ixy="-3.970466940254533e-23" ixz="1.294745805356161e-11" iyy="1.3378883884262557e-07" iyz="0.0" izz="4.9622899604909715e-08"/>
    </inertial>
    <visual>
      <origin rpy="0 0 0" xyz="0.002445 -0.0205 -0.001"/>
      <geometry>
        <mesh filename="package://mybot_description/meshes/garra/lat21.dae" scale="0.001 0.001 0.001"/>
      </geometry>
    </visual>
    <collision>
      <origin rpy="0 0 0" xyz="0.002445 -0.0205 -0.001"/>
      <geometry>
        <mesh filename="package://mybot_description/meshes/garra/lat21.dae" scale="0.001 0.001 0.001"/>
      </geometry>
    </collision>
  </link>
  <link name="servo_garra1">
    <inertial>
      <origin rpy="0 0 0" xyz="0.0003331581426503209 0.00010673599128592421 0.010000547183940757"/>
      <mass value="0.001"/>
      <inertia ixx="6.084896121919108e-06" ixy="7.673237329744245e-10" ixz="2.6844653998574326e-10" iyy="5.525444825215397e-06" iyz="-4.006713086347275e-10" izz="9.353516497648977e-06"/>
    </inertial>
    <visual>
      <origin rpy="0 0 0" xyz="-0.003609 5.8e-05 -0.004"/>
      <geometry>
        <mesh filename="package://mybot_description/meshes/garra/servo_garra1.dae" scale="0.001 0.001 0.001"/>
      </geometry>
    </visual>
    <collision>
      <origin rpy="0 0 0" xyz="-0.003609 5.8e-05 -0.004"/>
      <geometry>
        <mesh filename="package://mybot_description/meshes/garra/servo_garra1.dae" scale="0.001 0.001 0.001"/>
      </geometry>
    </collision>
  </link>
  <link name="base_camera1">
    <inertial>
      <origin rpy="0 0 0" xyz="-0.004389339547781822 0.020361286436828687 0.001500000342726699"/>
      <mass value="0.0001"/>
      <inertia ixx="1.9742676232972737e-06" ixy="3.353038926051923e-07" ixz="-1.641126335305207e-21" iyy="2.1544513492515026e-06" iyz="1.1249656330721176e-21" izz="4.115104278945627e-06"/>
    </inertial>
    <visual>
      <origin rpy="0 0 0" xyz="-0.005038 0.0205 -0.0252"/>
      <geometry>
        <mesh filename="package://mybot_description/meshes/garra/base_camera1.dae" scale="0.001 0.001 0.001"/>
      </geometry>
    </visual>
    <collision>
      <origin rpy="0 0 0" xyz="-0.005038 0.0205 -0.0252"/>
      <geometry>
        <mesh filename="package://mybot_description/meshes/garra/base_camera1.dae" scale="0.001 0.001 0.001"/>
      </geometry>
    </collision>
  </link>
  <link name="garra1garrabraco1">
    <inertial>
      <origin rpy="0 0 0" xyz="-0.0037506353032803787 0.05642585700103959 0.0018237999124817317"/>
      <mass value="2.8498940e-03"/>
      <inertia ixx="1.1175580e-05" ixy="0.0" ixz="0.0" iyy="1.1192413e-05" iyz="0.0" izz="2.0712558e-05"/>
    </inertial>
    <visual>
      <origin rpy="0 0 0" xyz="-0.027109 -0.009942 -0.014"/>
      <geometry>
        <mesh filename="package://mybot_description/meshes/garra/arm.dae" scale="0.001 0.001 0.001"/>
      </geometry>
    </visual>
    <collision>
      <origin rpy="0 0 0" xyz="-0.027109 -0.009942 -0.014"/>
      <geometry>
        <mesh filename="package://mybot_description/meshes/garra/arm.dae" scale="0.001 0.001 0.001"/>
      </geometry>
    </collision>
  </link>
  <link name="garra1garradireita1">
    <inertial>
      <origin rpy="0 0 0" xyz="0.010935004857829403 0.022288541926215877 0.00183118936157051"/>
      <mass value="0.80e-02"/>
      <inertia ixx="1.1175580e-05" ixy="0.0" ixz="0.0" iyy="1.1192413e-05" iyz="0.0" izz="2.0712558e-05"/>
    </inertial>
    <visual>
      <origin rpy="0 0 0" xyz="-0.023009 -0.086931 -0.0205"/>
      <geometry>
        <mesh filename="package://mybot_description/meshes/garra/direita.dae" scale="0.001 0.001 0.001"/>
      </geometry>
      <material name="green"/>
    </visual>
    <collision>
      <origin rpy="0 0 0" xyz="-0.023009 -0.086931 -0.0205"/>
      <geometry>
        <mesh filename="package://mybot_description/meshes/garra/direita.dae" scale="0.001 0.001 0.001"/>
      </geometry>
    </collision>
  </link>
  <link name="garra1garraesquerda1">
    <inertial>
      <origin rpy="0 0 0" xyz="-0.009562998839609715 0.0191706945123718 0.0023786783548043755"/>
      <mass value="0.80e-03"/>
      <inertia ixx="1.1175580e-05" ixy="0.0" ixz="0.0" iyy="1.1192413e-05" iyz="0.0" izz="2.0712558e-05"/>
    </inertial>
    <visual>
      <origin rpy="0 0 0" xyz="-0.006109 -0.088614 -0.0205"/>
      <material name="green"/>
      <geometry>
        <mesh filename="package://mybot_description/meshes/garra/esquerda.dae" scale="0.001 0.001 0.001"/>
      </geometry>
    </visual>
    <collision>
      <origin rpy="0 0 0" xyz="-0.006109 -0.088614 -0.0205"/>
      <geometry>
        <mesh filename="package://mybot_description/meshes/garra/esquerda.dae" scale="0.001 0.001 0.001"/>
      </geometry>
    </collision>
  </link>
  <joint name="Rigid1" type="fixed">
    <origin rpy="0 0 0" xyz="0.007563 -0.0205 0.001"/>
    <parent link="base_link_garra"/>
    <child link="lat31"/>
  </joint>
  <joint name="Rigid2" type="fixed">
    <origin rpy="0 0 0" xyz="-0.016 0.0 0.001"/>
    <parent link="base_link_garra"/>
    <child link="lat11"/>
  </joint>
  <joint name="Rigid3" type="fixed">
    <origin rpy="0 0 0" xyz="-0.002445 0.0205 0.001"/>
    <parent link="base_link_garra"/>
    <child link="lat21"/>
  </joint>
  <joint name="Rigid4" type="fixed">
    <origin rpy="0 0 0" xyz="0.003609 -5.8e-05 0.004"/>
    <parent link="base_link_garra"/>
    <child link="servo_garra1"/>
  </joint>
  <joint name="Rigid5" type="fixed">
    <origin rpy="0 0 0" xyz="-0.002525 0.0 0.0242"/>
    <parent link="lat31"/>
    <child link="base_camera1"/>
  </joint>
  <joint name="joint1" type="revolute">
    <origin rpy="0 0 0" xyz="0.0235 0.01 0.01"/>
    <limit effort="1" lower="-1.50" upper="1.5" velocity="0.1"/>
    <parent link="servo_garra1"/>
    <child link="garra1garrabraco1"/>
    <axis xyz="1.0 0.0 0.0"/>
  </joint>
  <joint name="joint2" type="revolute">
    <origin rpy="0 0 0" xyz="-0.0041 0.076989 0.0065"/>
    <limit effort="1" lower="-1" upper="0" velocity="0.1"/>
    <parent link="garra1garrabraco1"/>
    <child link="garra1garradireita1"/>
    <axis xyz="0.0 -0.0 1.0"/>
    <dynamics damping="0.02" friction="0.0"/>
  </joint>
  <joint name="joint3" type="revolute">
    <origin rpy="0 0 0" xyz="-0.021 0.078672 0.0065"/>
    <limit effort="1" lower="-1" upper="0" velocity="0.1"/>
    <parent link="garra1garrabraco1"/>
    <child link="garra1garraesquerda1"/>
    <mimic joint="joint2" multiplier="1" offset="0"/>
    <axis xyz="0.0 -0.0 -1.0"/>
    <dynamics damping="0.02" friction="0.0"/>
  </joint>
</robot>

