<?xml version="1.0" ?>
<robot name="mybot" xmlns:xacro="http://ros.org/wiki/xacro">
  <xacro:include filename="$(find mybot_description)/urdf/common_properties.xacro"/>
  <xacro:include filename="$(find mybot_description)/urdf/mybot.gazebo.xacro"/>


  
  <link name="base_footprint"/>

  <joint name="base_joint" type="fixed">
    <parent link="base_footprint"/>
    <child link="base_link"/>
    <origin xyz="0.0 0.0 0.010" rpy="0 0 0"/>
  </joint>

  <link name="base_link">
    <visual>
      <origin xyz="-0.032 0 0.0" rpy="0 0 0"/>
      <geometry>
        <mesh filename="package://mybot_description/meshes/bases/burger_base.stl" scale="0.001 0.001 0.001"/>
      </geometry>
      <material name="light_black"/>
    </visual>

    <collision>
      <origin xyz="-0.032 0 0.070" rpy="0 0 0"/>
      <geometry>
        <box size="0.140 0.140 0.143"/>
      </geometry>
    </collision>

    <inertial>
      <origin xyz="0 0 0" rpy="0 0 0"/>
      <mass value="8.2573504e-01"/>
      <inertia ixx="2.2124416e-03" ixy="-1.2294101e-05" ixz="3.4938785e-05"
               iyy="2.1193702e-03" iyz="-5.0120904e-06"
               izz="2.0064271e-03" />
    </inertial>
  </link>

  <joint name="wheel_left_joint" type="continuous">
    <parent link="base_link"/>
    <child link="wheel_left_link"/>
    <origin xyz="0.0 0.08 0.023" rpy="-1.57 0 0"/>
    <axis xyz="0 0 1"/>
  </joint>

  <link name="wheel_left_link">
    <visual>
      <origin xyz="0 0 0" rpy="1.57 0 0"/>
      <geometry>
        <mesh filename="package://mybot_description/meshes/wheels/left_tire.stl" scale="0.001 0.001 0.001"/>
      </geometry>
      <material name="dark"/>
    </visual>

    <collision>
      <origin xyz="0 0 0" rpy="0 0 0"/>
      <geometry>
        <cylinder length="0.018" radius="0.033"/>
      </geometry>
    </collision>

    <inertial>
      <origin xyz="0 0 0" />
      <mass value="2.8498940e-02" />
      <inertia ixx="1.1175580e-05" ixy="-4.2369783e-11" ixz="-5.9381719e-09"
               iyy="1.1192413e-05" iyz="-1.4400107e-11"
               izz="2.0712558e-05" />
      </inertial>
  </link>

  <joint name="wheel_right_joint" type="continuous">
    <parent link="base_link"/>
    <child link="wheel_right_link"/>
    <origin xyz="0.0 -0.080 0.023" rpy="-1.57 0 0"/>
    <axis xyz="0 0 1"/>
  </joint>

  <link name="wheel_right_link">
    <visual>
      <origin xyz="0 0 0" rpy="1.57 0 0"/>
      <geometry>
        <mesh filename="package://mybot_description/meshes/wheels/right_tire.stl" scale="0.001 0.001 0.001"/>
      </geometry>
      <material name="dark"/>
    </visual>

    <collision>
      <origin xyz="0 0 0" rpy="0 0 0"/>
      <geometry>
        <cylinder length="0.018" radius="0.033"/>
      </geometry>
    </collision>

    <inertial>
      <origin xyz="0 0 0" />
      <mass value="2.8498940e-02" />
      <inertia ixx="1.1175580e-05" ixy="-4.2369783e-11" ixz="-5.9381719e-09"
               iyy="1.1192413e-05" iyz="-1.4400107e-11"
               izz="2.0712558e-05" />
      </inertial>
  </link>

  <joint name="caster_back_joint" type="fixed">
    <parent link="base_link"/>
    <child link="caster_back_link"/>
    <origin xyz="-0.081 0 -0.004" rpy="-1.57 0 0"/>
  </joint>

  <link name="caster_back_link">
    <collision>
      <origin xyz="0 0.001 0" rpy="0 0 0"/>
      <geometry>
        <box size="0.030 0.009 0.020"/>
      </geometry>
    </collision>

    <inertial>
      <origin xyz="0 0 0" />
      <mass value="0.005" />
      <inertia ixx="0.001" ixy="0.0" ixz="0.0"
               iyy="0.001" iyz="0.0"
               izz="0.001" />
    </inertial>
  </link>

  <joint name="imu_joint" type="fixed">
    <parent link="base_link"/>
    <child link="imu_link"/>
    <origin xyz="-0.032 0 0.068" rpy="0 0 0"/>
  </joint>

  <link name="imu_link"/>

  <joint name="scan_joint" type="fixed">
    <parent link="base_link"/>
    <child link="base_scan"/>
    <origin xyz="-0.032 0 0.172" rpy="0 0 0"/>
  </joint>

  <link name="base_scan">
    <visual>
      <origin xyz="0 0 0.0" rpy="0 0 0"/>
      <geometry>
        <mesh filename="package://mybot_description/meshes/sensors/lds.stl" scale="0.001 0.001 0.001"/>
      </geometry>
      <material name="dark"/>
    </visual>

    <collision>
      <origin xyz="0.015 0 -0.0065" rpy="0 0 0"/>
      <geometry>
        <cylinder length="0.0315" radius="0.055"/>
      </geometry>
    </collision>

    <inertial>
      <mass value="0.114" />
      <origin xyz="0 0 0" />
      <inertia ixx="0.001" ixy="0.0" ixz="0.0"
               iyy="0.001" iyz="0.0"
               izz="0.001" />
    </inertial>
  </link>
<!-- camera turtlebot3 insper-->
  <joint name="camera_joint" type="fixed">
    <origin xyz="0.05 -0.011 0.138" rpy="0 0.0 0"/>
    <parent link="base_link"/>
    <child link="camera_link"/>
  </joint>

  <link name="camera_link">
    <visual>
        <origin xyz="0.005 0.011 0.013" rpy="0 0 0"/>
        <geometry>
            <box size="0.005 0.030 0.027"/>
        </geometry>
    </visual>
    <collision>
      <origin xyz="0.005 0.011 0.013" rpy="0 0 0"/>
      <geometry>
        <box size="0.005 0.030 0.027"/>
      </geometry>
    </collision>
  </link>

  <joint name="camera_rgb_joint" type="fixed">
    <origin xyz="0.003 0.011 0.009" rpy="0 0 0"/>
    <parent link="camera_link"/>
    <child link="camera_rgb_frame"/>
  </joint>
  <link name="camera_rgb_frame"/>

  <joint name="camera_rgb_optical_joint" type="fixed">
    <origin xyz="0 0 0" rpy="-1.57 0 -1.57"/>
    <parent link="camera_rgb_frame"/>
    <child link="camera_rgb_optical_frame"/>
  </joint>
  <link name="camera_rgb_optical_frame"/>

<!-- bumper turtlebot3 insper-->
  <link name="bumper_link">
    <inertial>
        <origin xyz="0.0 0.0 0.0" rpy="0 1.0 0"/>
        <mass value="0.0000000001"/>
        <inertia ixx="0.00000001" ixy="0.00000001" ixz="0.00000001" iyy="0.00000001" iyz="0.00000001" izz="0.00000001"/>
    </inertial>
    <visual>
        <origin xyz="0.0 0.0 0.0" rpy="0.0 1.57 0"/>
        <geometry>
            <cylinder radius="0.015" length="0.015"/>
        </geometry>
      <material name="green"/>
    </visual>
    <collision name="base_collision">
        <origin xyz="0.0 0.0 0.0" rpy="0.0 1.57 0.0"/>
        <geometry>
            <cylinder radius="0.015" length="0.015"/>
        </geometry>
    </collision>
  </link>
  <joint name="bumper_joint" type="fixed">
      <origin xyz="0.04 0.0 0.015" rpy="0.0 0.0 0.0"/>
      <parent link="base_link"/>
      <child link="bumper_link"/>
  </joint>

<!-- garra turtlebot3 insper-->

  <joint name="base_joint_garra" type="fixed">
    <parent link="base_link"/>
    <child link="base_link_garra"/>
    <origin xyz="0.044 0.005 0.108" rpy="0 0 -1.57"/>
  </joint>


  <link name="base_link_garra">
    <inertial>
      <origin rpy="0 0 0" xyz="0.0005 -0.0001 0.002"/>
      <mass value="0.0001"/>
      <inertia ixx="1.9768356736455373e-06" ixy="3.3842609487814834e-07" ixz="3.3087224502121107e-23" iyy="2.1568932661454165e-06" iyz="-2.274746684520826e-23" izz="4.120108098287789e-06"/>
    </inertial>
    <visual>
      <origin rpy="0 0 0" xyz="0 0 0"/>
      <geometry>
        <mesh filename="package://mybot_description/meshes/garra/base_link_garra.dae" scale="0.001 0.001 0.001"/>
      </geometry>
      <gazebo reference="base_link_garra">
    </gazebo>
    </visual>
    <collision>
      <origin rpy="0 0 0" xyz="0 0 0"/>
      <geometry>
        <mesh filename="package://mybot_description/meshes/garra/base_link_garra.dae" scale="0.001 0.001 0.001"/>
      </geometry>
    </collision>
  </link>

  <link name="lat31">
    <inertial>
      <origin rpy="0 0 0" xyz="-0.005014384312211391 -0.0015000010654330244 0.013948367968184407"/>
      <mass value="0.0001"/>
      <inertia ixx="8.662089264671677e-08" ixy="0.0" ixz="1.2947458053521905e-11" iyy="1.3378883884262552e-07" iyz="0.0" izz="4.9622899604909504e-08"/>
    </inertial>
    <visual>
      <origin rpy="0 0 0" xyz="-0.007563 0.0205 -0.001"/>
      <geometry>
        <mesh filename="package://mybot_description/meshes/garra/lat31.dae" scale="0.001 0.001 0.001"/>
      </geometry>
      <gazebo reference="lat31">
    </gazebo>
    </visual>
    <collision>
      <origin rpy="0 0 0" xyz="-0.007563 0.0205 -0.001"/>
      <geometry>
        <mesh filename="package://mybot_description/meshes/garra/lat31.dae" scale="0.001 0.001 0.001"/>
      </geometry>
    </collision>
  </link>

  <link name="lat11">
    <inertial>
      <origin rpy="0 0 0" xyz="-0.00149999999999997 0.004954936394439788 0.013948367968184407"/>
      <mass value="0.0001"/>
      <inertia ixx="1.3378883884262488e-07" ixy="-2.6469779601696886e-23" ixz="0.0" iyy="8.66208926467172e-08" iyz="1.294745805340279e-11" izz="4.962289960490908e-08"/>
    </inertial>
    <visual>
      <origin rpy="0 0 0" xyz="0.016 0.0 -0.001"/>
      <geometry>
        <mesh filename="package://mybot_description/meshes/garra/lat11.dae" scale="0.001 0.001 0.001"/>
      </geometry>
      <gazebo reference="lat11">     
    </gazebo>
    </visual>
    <collision>
      <origin rpy="0 0 0" xyz="0.016 0.0 -0.001"/>
      <geometry>
        <mesh filename="package://mybot_description/meshes/garra/lat11.dae" scale="0.001 0.001 0.001"/>
      </geometry>
    </collision>
  </link>

  <link name="lat21">
    <inertial>
      <origin rpy="0 0 0" xyz="0.004954582993387833 0.0014999998509883788 0.013948367968184407"/>
      <mass value="0.0001"/>
      <inertia ixx="8.66208926467172e-08" ixy="-3.970466940254533e-23" ixz="1.294745805356161e-11" iyy="1.3378883884262557e-07" iyz="0.0" izz="4.9622899604909715e-08"/>
    </inertial>
    <visual>
      <origin rpy="0 0 0" xyz="0.002445 -0.0205 -0.001"/>
      <geometry>
        <mesh filename="package://mybot_description/meshes/garra/lat21.dae" scale="0.001 0.001 0.001"/>
      </geometry>
    </visual>
    <collision>
      <origin rpy="0 0 0" xyz="0.002445 -0.0205 -0.001"/>
      <geometry>
        <mesh filename="package://mybot_description/meshes/garra/lat21.dae" scale="0.001 0.001 0.001"/>
      </geometry>
    </collision>
  </link>

  <link name="servo_garra1">
    <inertial>
      <origin rpy="0 0 0" xyz="0.0003331581426503209 0.00010673599128592421 0.010000547183940757"/>
      <mass value="0.001"/>
      <inertia ixx="6.084896121919108e-06" ixy="7.673237329744245e-10" ixz="2.6844653998574326e-10" iyy="5.525444825215397e-06" iyz="-4.006713086347275e-10" izz="9.353516497648977e-06"/>
    </inertial>
    <visual>
      <origin rpy="0 0 0" xyz="-0.003609 5.8e-05 -0.004"/>
      <geometry>
        <mesh filename="package://mybot_description/meshes/garra/servo_garra1.dae" scale="0.001 0.001 0.001"/>
      </geometry>
    </visual>
    <collision>
      <origin rpy="0 0 0" xyz="-0.003609 5.8e-05 -0.004"/>
      <geometry>
        <mesh filename="package://mybot_description/meshes/garra/servo_garra1.dae" scale="0.001 0.001 0.001"/>
      </geometry>
    </collision>
  </link>

  <link name="base_camera1">
    <inertial>
      <origin rpy="0 0 0" xyz="-0.004389339547781822 0.020361286436828687 0.001500000342726699"/>
      <mass value="0.0001"/>
      <inertia ixx="1.9742676232972737e-06" ixy="3.353038926051923e-07" ixz="-1.641126335305207e-21" iyy="2.1544513492515026e-06" iyz="1.1249656330721176e-21" izz="4.115104278945627e-06"/>
    </inertial>
    <visual>
      <origin rpy="0 0 0" xyz="-0.005038 0.0205 -0.0252"/>
      <geometry>
        <mesh filename="package://mybot_description/meshes/garra/base_camera1.dae" scale="0.001 0.001 0.001"/>
      </geometry>
    </visual>
    <collision>
      <origin rpy="0 0 0" xyz="-0.005038 0.0205 -0.0252"/>
      <geometry>
        <mesh filename="package://mybot_description/meshes/garra/base_camera1.dae" scale="0.001 0.001 0.001"/>
      </geometry>
    </collision>
  </link>

  <link name="garra1garrabraco1">
    <inertial>
      <origin rpy="0 0 0" xyz="-0.0037506353032803787 0.05642585700103959 0.0018237999124817317"/>
      <mass value="2.8498940e-03" />
      <inertia ixx="1.1175580e-05" ixy="0.0" ixz="0.0"
               iyy="1.1192413e-05" iyz="0.0"
               izz="2.0712558e-05" />
    </inertial>
    <visual>
      <origin rpy="0 0 0" xyz="-0.027109 -0.009942 -0.014"/>
      <geometry>
        <mesh filename="package://mybot_description/meshes/garra/arm.dae" scale="0.001 0.001 0.001"/>
      </geometry>
    </visual>
    <collision>
      <origin rpy="0 0 0" xyz="-0.027109 -0.009942 -0.014"/>
      <geometry>
        <mesh filename="package://mybot_description/meshes/garra/arm.dae" scale="0.001 0.001 0.001"/>
      </geometry>
    </collision>
  </link>

  <link name="garra1garradireita1">
    <inertial>
      <origin rpy="0 0 0" xyz="0.010935004857829403 0.022288541926215877 0.00183118936157051"/>
      <mass value="0.80e-02" />
      <inertia ixx="1.1175580e-05" ixy="0.0" ixz="0.0"
               iyy="1.1192413e-05" iyz="0.0"
               izz="2.0712558e-05" />
    </inertial>
    <visual>
      <origin rpy="0 0 0" xyz="-0.023009 -0.086931 -0.0205"/>
      <geometry>
        <mesh filename="package://mybot_description/meshes/garra/direita.dae" scale="0.001 0.001 0.001"/>
      </geometry>
      <material name="green"/>
    </visual>
    <collision>
      <origin rpy="0 0 0" xyz="-0.023009 -0.086931 -0.0205"/>
      <geometry>
        <mesh filename="package://mybot_description/meshes/garra/direita.dae" scale="0.001 0.001 0.001"/>
      </geometry>
      </collision>
  </link>

  <link name="garra1garraesquerda1">
    <inertial>
      <origin rpy="0 0 0" xyz="-0.009562998839609715 0.0191706945123718 0.0023786783548043755"/>
      <mass value="0.80e-03" />
      <inertia ixx="1.1175580e-05" ixy="0.0" ixz="0.0"
               iyy="1.1192413e-05" iyz="0.0"
               izz="2.0712558e-05" />
    </inertial>
    <visual>
      <origin rpy="0 0 0" xyz="-0.006109 -0.088614 -0.0205"/>
      <material name="green"/>
      <geometry>
       <mesh filename="package://mybot_description/meshes/garra/esquerda.dae" scale="0.001 0.001 0.001"/>
      </geometry>
    </visual>
    <collision>
      <origin rpy="0 0 0" xyz="-0.006109 -0.088614 -0.0205"/>
      <geometry>
        <mesh filename="package://mybot_description/meshes/garra/esquerda.dae" scale="0.001 0.001 0.001"/>
      </geometry>
    </collision>
  </link>

  <joint name="Rigid1" type="fixed">
    <origin rpy="0 0 0" xyz="0.007563 -0.0205 0.001"/>
    <parent link="base_link_garra"/>
    <child link="lat31"/>
  </joint>

  <joint name="Rigid2" type="fixed">
    <origin rpy="0 0 0" xyz="-0.016 0.0 0.001"/>
    <parent link="base_link_garra"/>
    <child link="lat11"/>
  </joint>

  <joint name="Rigid3" type="fixed">
    <origin rpy="0 0 0" xyz="-0.002445 0.0205 0.001"/>
    <parent link="base_link_garra"/>
    <child link="lat21"/>
  </joint>

  <joint name="Rigid4" type="fixed">
    <origin rpy="0 0 0" xyz="0.003609 -5.8e-05 0.004"/>
    <parent link="base_link_garra"/>
    <child link="servo_garra1"/>
  </joint>

  <joint name="Rigid5" type="fixed">
    <origin rpy="0 0 0" xyz="-0.002525 0.0 0.0242"/>
    <parent link="lat31"/>
    <child link="base_camera1"/>
  </joint>

  <joint name="joint1" type="revolute">
    <origin rpy="0 0 0" xyz="0.0235 0.01 0.01"/>
    <limit effort="1" lower="-1.50" upper="1.5" velocity="0.1"/>
    <parent link="servo_garra1"/>
    <child link="garra1garrabraco1"/>
    <axis xyz="1.0 0.0 0.0"/>
  </joint>

  <joint name="joint2" type="revolute">
    <origin rpy="0 0 0" xyz="-0.0041 0.076989 0.0065"/>
    <limit effort="1" lower="-1" upper="0" velocity="0.1"/>
    <parent link="garra1garrabraco1"/>
    <child link="garra1garradireita1"/>
    <axis xyz="0.0 -0.0 1.0"/>
    <dynamics damping="0.02" friction="0.0" />
  </joint>

  <joint name="joint3" type="revolute">
    <origin rpy="0 0 0" xyz="-0.021 0.078672 0.0065"/>
    <limit effort="1" lower="-1" upper="0" velocity="0.1"/>
    <parent link="garra1garrabraco1"/>
    <child link="garra1garraesquerda1"/>
    <mimic joint="joint2" multiplier="1" offset="0" />
    <axis xyz="0.0 -0.0 -1.0"/>
    <dynamics damping="0.02" friction="0.0" />
  </joint>


</robot>
